<?xml version="1.0"?>
<robot xmlns:xacro="http://www.ros.org/wiki/xacro" >

    <xacro:include filename="inertial_macros.xacro"/>

    <material name="gray">
        <color rgba="0.5 0.5 0.5 1" />
    </material>

    <material name="black">
        <color rgba="0 0 0 1" />
    </material>

    <material name="red">
        <color rgba="1 0 0 1" />
    </material>

    <!-- BASE LINK -->

    <link name="base_link">

    </link>

    <!-- BASE_FOOTPRINT LINK-->
    <joint name="base_footprint_joint" type="fixed">
        <parent link="base_link"/>
        <child link="base_footprint"/>
        <origin xyz="0 0 0" rpy="0 0 0"/>
    </joint>

    <link name="base_footprint">
    </link>

    <!-- CHASSIS LINK -->

    <joint name="chassis_joint" type="fixed">
        <parent link="base_link"/>
        <child link="chassis"/>
        <origin xyz="-0.42 0 0"/>
    </joint>

    <link name="chassis">
        <visual>
            <origin xyz="0.45 0 0.09"/>
            <geometry>
                <box size="0.9 0.56 0.18"/>
            </geometry>

            <material name="gray"/>
        </visual>

        <collision>
            <origin xyz="0.45 0 0.09"/>
            <geometry>
                <box size="0.9 0.56 0.18"/>
            </geometry>
        </collision>
        <xacro:inertial_box mass="20" x="0.9" y="0.56" z="0.18">
            <origin xyz="0.45 0 0.09" rpy="0 0 0"/>
        </xacro:inertial_box>
    </link>

    <gazebo reference="chassis">
        <material>Gazebo/gray</material>
    </gazebo>

    <!-- LEFT WHEEL LINK -->

    <joint name="left_wheel_joint" type="continuous">
        <parent link="base_link"/>
        <child link="left_wheel"/>
        <origin xyz="0 0.2675 0" rpy="-${pi/2} 0 0"/>
        <axis xyz="0 0 1"/>
    </joint>

    <link name="left_wheel">
        <visual>
            <geometry>
                <cylinder radius="0.078" length="0.035"/>
            </geometry>

            <material name="black"/>
        </visual>
        
        <collision>
            <geometry>
                <cylinder radius="0.078" length="0.035"/>
            </geometry>
        </collision>

        <xacro:inertial_cylinder mass="1" length="0.035" radius="0.078">
            <origin xyz="0 0 0" rpy="0 0 0"/>
        </xacro:inertial_cylinder>

    </link>

    <gazebo reference="left_wheel">
        <material>Gazebo/black</material>
    </gazebo>

    <!-- RIGHT WHEEL LINK -->

    <joint name="right_wheel_joint" type="continuous">
        <parent link="base_link"/>
        <child link="right_wheel"/>
        <origin xyz="0 -0.2675 0" rpy="${pi/2} 0 0"/>
        <axis xyz="0 0 -1"/>
    </joint>

    <link name="right_wheel">
        <visual>
            <geometry>
                <cylinder radius="0.078" length="0.035"/>
            </geometry>

            <material name="black"/>
        </visual>

        <collision>
            <geometry>
                <cylinder radius="0.078" length="0.035"/>
            </geometry>
        </collision>

        <xacro:inertial_cylinder mass="1" length="0.035" radius="0.078">
            <origin xyz="0 0 0" rpy="0 0 0"/>
        </xacro:inertial_cylinder>

    </link>

    <gazebo reference="right_wheel">
        <material>Gazebo/black</material>
    </gazebo>


    <!-- BACK CASTER WHEEL LINK --> 
    <joint name="back_caster_wheel_joint" type="fixed">
        <parent link="chassis"/>
        <child link="caster_wheel_back"/>
        <origin xyz="0.10 0 0" />
    </joint>
    
    <link name="caster_wheel_back">
        <visual>
            <geometry>
                <sphere radius="0.078"/>
            </geometry>
            <material name="black"/>
        </visual>

        <collision>
            <geometry>
                <sphere radius="0.078"/>
            </geometry>
        </collision>

        <xacro:inertial_sphere mass="1" radius="0.078">
            <origin xyz="0 0 0" rpy="0 0 0"/>
        </xacro:inertial_sphere>
    </link>
    
    <gazebo reference="caster_wheel_back">
        <material>Gazebo/black</material>
        <mu1 value="0.001"/>
        <mu2 value="0.001"/>
    </gazebo>

        <!-- RIGHT CASTER WHEEL LINK --> 
    <joint name="right_caster_wheel_joint" type="fixed">
        <parent link="chassis"/>
        <child link="caster_wheel_front_right"/>
        <origin xyz="0.80 0.16 0" />
    </joint>
    
    <link name="caster_wheel_front_right">
        <visual>
            <geometry>
                <sphere radius="0.078"/>
            </geometry>
            <material name="black"/>
        </visual>

        <collision>
            <geometry>
                <sphere radius="0.078"/>
            </geometry>
        </collision>

        <xacro:inertial_sphere mass="1" radius="0.078">
            <origin xyz="0 0 0" rpy="0 0 0"/>
        </xacro:inertial_sphere>
    </link>

    <gazebo reference="caster_wheel_front_right">
        <material>Gazebo/black</material>
        <mu1 value="0.001"/>
        <mu2 value="0.001"/>
    </gazebo>

        <!-- LEFT CASTER WHEEL LINK --> 
    <joint name="left_caster_wheel_joint" type="fixed">
        <parent link="chassis"/>
        <child link="caster_wheel_front_left"/>
        <origin xyz="0.80 -0.16 0" />
    </joint>

    <link name="caster_wheel_front_left">
        <visual>
            <geometry>
                <sphere radius="0.078"/>
            </geometry>
            <material name="black"/>
        </visual>

        <collision>
            <geometry>
                <sphere radius="0.078"/>
            </geometry>
        </collision>

        <xacro:inertial_sphere mass="1" radius="0.078">
            <origin xyz="0 0 0" rpy="0 0 0"/>
        </xacro:inertial_sphere>
    </link>

    <gazebo reference="caster_wheel_front_left">
        <material>Gazebo/black</material>
        <mu1 value="0.001"/>
        <mu2 value="0.001"/>
    </gazebo>

</robot>